<?xml version="1.0"?>
<robot name="diffbot" xmlns:xacro="http://www.ros.org/wiki/xacro">

  <!-- Propiedades reutilizables -->
  <xacro:property name="base_length" value="0.4"/>
  <xacro:property name="base_width"  value="0.3"/>
  <xacro:property name="base_height" value="0.1"/>
  <xacro:property name="wheel_radius" value="0.05"/>
  <xacro:property name="wheel_width"  value="0.04"/>
  <xacro:property name="wheel_separation" value="0.32"/>

  <!-- Materiales -->
  <material name="blue"><color rgba="0.2 0.4 0.8 1.0"/></material>
  <material name="black"><color rgba="0.1 0.1 0.1 1.0"/></material>
  <material name="grey"><color rgba="0.5 0.5 0.5 1.0"/></material>

  <!-- base_footprint: frame en el suelo -->
  <link name="base_footprint"/>

  <joint name="base_footprint_to_base_link" type="fixed">
    <parent link="base_footprint"/>
    <child  link="base_link"/>
    <origin xyz="0 0 ${wheel_radius}" rpy="0 0 0"/>
  </joint>

  <!-- base_link: chasis -->
  <link name="base_link">
    <visual>
      <geometry>
        <box size="${base_length} ${base_width} ${base_height}"/>
      </geometry>
      <material name="blue"/>
    </visual>
    <collision>
      <geometry>
        <box size="${base_length} ${base_width} ${base_height}"/>
      </geometry>
    </collision>
    <inertial>
      <mass value="2.0"/>
      <inertia ixx="0.02" ixy="0" ixz="0" iyy="0.04" iyz="0" izz="0.05"/>
    </inertial>
  </link>

  <!-- Macro para crear una rueda -->
  <xacro:macro name="wheel" params="prefix y_reflect">
    <link name="${prefix}_wheel_link">
      <visual>
        <origin xyz="0 0 0" rpy="${pi/2} 0 0"/>
        <geometry>
          <cylinder radius="${wheel_radius}" length="${wheel_width}"/>
        </geometry>
        <material name="black"/>
      </visual>
      <collision>
        <origin xyz="0 0 0" rpy="${pi/2} 0 0"/>
        <geometry>
          <cylinder radius="${wheel_radius}" length="${wheel_width}"/>
        </geometry>
      </collision>
      <inertial>
        <mass value="0.1"/>
        <inertia ixx="0.0001" ixy="0" ixz="0" iyy="0.0001" iyz="0" izz="0.0001"/>
      </inertial>
    </link>

    <joint name="${prefix}_wheel_joint" type="continuous">
      <parent link="base_link"/>
      <child  link="${prefix}_wheel_link"/>
      <origin xyz="0 ${y_reflect * wheel_separation/2} ${-base_height/2}" rpy="0 0 0"/>
      <axis xyz="0 1 0"/>
    </joint>
  </xacro:macro>

  <xacro:wheel prefix="left"  y_reflect="1"/>
  <xacro:wheel prefix="right" y_reflect="-1"/>

  <!-- Caster esfera delantera -->
  <link name="caster_link">
    <visual>
      <geometry><sphere radius="0.025"/></geometry>
      <material name="grey"/>
    </visual>
    <collision>
      <geometry><sphere radius="0.025"/></geometry>
    </collision>
    <inertial>
      <mass value="0.05"/>
      <inertia ixx="0.00001" ixy="0" ixz="0" iyy="0.00001" iyz="0" izz="0.00001"/>
    </inertial>
  </link>

  <joint name="caster_joint" type="fixed">
    <parent link="base_link"/>
    <child  link="caster_link"/>
    <origin xyz="${base_length/2 - 0.05} 0 ${-base_height/2 - 0.025}" rpy="0 0 0"/>
  </joint>

  <!-- LiDAR encima del chasis -->
  <link name="lidar_link">
    <visual>
      <geometry><cylinder radius="0.04" length="0.04"/></geometry>
      <material name="grey"/>
    </visual>
    <collision>
      <geometry><cylinder radius="0.04" length="0.04"/></geometry>
    </collision>
    <inertial>
      <mass value="0.1"/>
      <inertia ixx="0.0001" ixy="0" ixz="0" iyy="0.0001" iyz="0" izz="0.0001"/>
    </inertial>
  </link>

  <joint name="lidar_joint" type="fixed">
    <parent link="base_link"/>
    <child  link="lidar_link"/>
    <origin xyz="0 0 ${base_height/2 + 0.02}" rpy="0 0 0"/>
  </joint>

</robot>
